Workbook

Sheet ключевые слова
A1: Введите ниже ключевые слова
A2: сбор
A3: запись
A4: систематизация
A5: накопление
A6: хранение
A7: уточнение (обновление, изменение)
A8: извлечение
A9: использование
A10: передача (распространение, предоставление, доступ)
A11: удаление
A12: уничтожение

Sheet данные для анализа
A1: поле для анализа: actions_category | B1: rkn:name_full | C1: rkn:address
A2: Сбор, систематизация, хранение, использование, уточнение (обновление, изменение), накопление, обезличивание, блокирование, уничтожение, передача в казначейство, банк, налоговую службу, федеральные фонды. | B2: федеральное государственное бюджетное образовательное учреждение высшего образования "Новосибирский государственный аграрный университет" | C2: 630039, г. Новосибирск, ул. Добролюбова, д. 160
A3: Сбор, систематизация, накопление, хранение, уточнение (обновление, изменение), использование, распространение (в том числе передача), уничтожение персональных данных. | B3: федеральное государственное бюджетное образовательное учреждение высшего профессионального образования "Волгоградский государственный архитектурно-строительный университет" | C3: 400074, Волгоградская обл., г. Волгоград, ул. Академическая, д. 1
A4: Сбор, запись, систематизация, накопление, хранение, уточнение (обновление, изменение), извлечение, использование, передача (распространение, предоставление, доступ), обезличивание, блокирование, удаление, уничтожение персональных данных. | B4: Федеральное государственное бюджетное образовательное учреждение высшего образования "Уральский государственный университет путей сообщения" | C4: 620034, Свердловская обл, Екатеринбург г, Колмогорова ул, д. 66
A5: путем смешанной обработки персональных данных с передачей информации по внутренней сети | B5: Государственное образовательное учреждение высшего профессионального образования "Московский государственный технический университет имени Н.Э.Баумана" | C5: 105005, г. Москва, ул. Бауманская 2-я, д. 5
A6: Сбор, систематизация, накопление, хранение, уточнение, распространение, обезличивание, уничтожение | B6: Государственное бюджетное образовательное учреждение высшего профессионального образования «Пермский государственный медицинский университет имени академика Е.А. Вагнера» Министерства здравоохранения Российской Федерации | C6: ул. Петропавловская, д. 26, г. Пермь, 614000
A7: смешанная обработка вышеуказанных персональных данных будет осуществляться с использованием ПЭВМ (информация доступна лишь для строго определенных сотрудников юридического лица), с передачей полученной информации по локальной сети. | B7: Федеральное государственное образовательное учреждение высшего профессионального образования "Военно-технический университет при Федеральном агентстве специального строительства" | C7: 143900, Московская обл.,г. Балашиха-11, ул. Карбышева, д. 8
A8: Формирование документации, необходимой для осуществления образовательной и научной деятельности. | B8: Государственное образовательное учреждение высшего профессионального образования "Московский государственный институт электроники и математики (технический университет)" | C8: Б.Трехсвятительский пер., д.1-3/12, стр.8, Москва, 109028
A9: Сбор, запись, систематизация, накопление, хранение, уточнение (обновление, изменение), извлечение, использование, передача, распространение, предоставление, блокирование, трансграничная передача, удаление, уничтожение персональных данных. | B9: Федеральное государственное бюджетное образовательное учреждение высшего образования "Сочинский государственный университет" | C9: 354000, Краснодарский край, г. Сочи, р-н Центральный, ул. Пластунская, д. 94
A10: сбор, запись, систематизация, накопление, хранение, уточнение (обновления, изменение), извлечение, использование, передача (распространение, предоставление, доступ), обезличивание, блокирование, удаление, уничтожение персональных данных. | B10: федеральное государственное бюджетное образовательное учреждение высшего профессионального образования "Шуйский государственный педагогический университет" | C10: 155908, Ивановская обл., г. Шуя, ул. Кооперативная, д. 24
A11: сбор, систематизация, накопление, хранение, уточнение, использование, распространение, блокирование, уничтожение | B11: Государственное автономное образовательное учреждение высшего образования Ленинградской области "Ленинградский государственный университет имени А.С. Пушкина" | C11: 196605, г. Санкт-Петербург, г. Пушкин, ш. Петербургское, д. 10
A12: Сбор, запись, систематизация, накопление, хранение, уточнение (обновление, изменение), извлечение, использование, передача (распространение, предоставление, доступ), обезличивание, блокирование, удаление, уничтожение. | B12: федеральное государственное бюджетное образовательное учреждение высшего профессионального образования "Новосибирский государственный университет экономики и управления "НИНХ" | C12: 630099, Новосибирская обл., г. Новосибирск, ул. Каменская, д. 56
... A130: обработка и хранение на информационных системах и бумажных носителях, работа с персональными документами сотрудников и студентов, ведение их личных дел и учета. | B130: Федеральное государственное бюджетное образовательное учреждение высшего профессионального образования "Оренбургский государственный педагогический университет" | C130: 460014, Оренбургская обл., г. Оренбург, ул. Советская, д. 19

Sheet разбиение по частям
A1: данные | B1: слово 1 | C1: слово 2 | D1: слово 3 | E1: слово 4 | F1: слово 5 | G1: слово 6 | H1: слово 7 | I1: слово 8 | J1: слово 9 | K1: слово 10 | L1: слово 11 | M1: слово 12 | N1: слово 13 | O1: слово 14 | P1: слово 15 | Q1: слово 16 | R1: слово 17 | S1: слово 18 | T1: слово 19 | U1: слово 20 | V1: слово 21
A2: ='данные для анализа'!A2 | B2: сбор | C2: систематизация | D2: хранение | E2: использование | F2: уточнение (обновление, изменение) | G2: накопление | H2: обезличивание | I2: блокирование | J2: уничтожение | K2: передача в казначейство | L2: банк | M2: налоговую службу | N2: федеральные фонды.
A3: ='данные для анализа'!A3 | B3: сбор | C3: систематизация | D3: накопление | E3: хранение | F3: уточнение (обновление, изменение) | G3: использование | H3: распространение (в том числе передача) | I3: уничтожение персональных данных.
A4: ='данные для анализа'!A4 | B4: сбор | C4: запись | D4: систематизация | E4: накопление | F4: хранение | G4: уточнение (обновление, изменение) | H4: извлечение | I4: использование | J4: передача (распространение, предоставление, доступ) | K4: обезличивание | L4: блокирование | M4: удаление | N4: уничтожение персональных данных.
A5: ='данные для анализа'!A5 | B5: путем смешанной обработки персональных данных с передачей информации по внутренней сети
A6: ='данные для анализа'!A6 | B6: сбор | C6: систематизация | D6: накопление | E6: хранение | F6: уточнение | G6: распространение | H6: обезличивание | I6: уничтожение
A7: ='данные для анализа'!A7 | B7: смешанная обработка вышеуказанных персональных данных будет осуществляться с использованием пэвм (информация доступна лишь для строго определенных сотрудников юридического лица) | C7: с передачей полученной информации по локальной сети.
A8: ='данные для анализа'!A8 | B8: формирование документации | C8: необходимой для осуществления образовательной и научной деятельности.
A9: ='данные для анализа'!A9 | B9: сбор | C9: запись | D9: систематизация | E9: накопление | F9: хранение | G9: уточнение (обновление, изменение) | H9: извлечение | I9: использование | J9: передача | K9: распространение | L9: предоставление | M9: блокирование | N9: трансграничная передача | O9: удаление | P9: уничтожение персональных данных.
A10: ='данные для анализа'!A10 | B10: сбор | C10: запись | D10: систематизация | E10: накопление | F10: хранение | G10: уточнение (обновления, изменение) | H10: извлечение | I10: использование | J10: передача (распространение, предоставление, доступ) | K10: обезличивание | L10: блокирование | M10: удаление | N10: уничтожение персональных данных.
A11: ='данные для анализа'!A11 | B11: сбор | C11: систематизация | D11: накопление | E11: хранение | F11: уточнение | G11: использование | H11: распространение | I11: блокирование | J11: уничтожение
A12: ='данные для анализа'!A12 | B12: сбор | C12: запись | D12: систематизация | E12: накопление | F12: хранение | G12: уточнение (обновление, изменение) | H12: извлечение | I12: использование | J12: передача (распространение, предоставление, доступ) | K12: обезличивание | L12: блокирование | M12: удаление | N12: уничтожение.
A13: ='данные для анализа'!A13 | B13: смешанная обработка
A14: ='данные для анализа'!A14 | B14: Смешанная обработка ПД с использованием ПЭВМ (информация доступна лишь для строго определенных сотрудников юридического лица) без передачи полученной информации с использованием сети общего пользования Интернет.
A15: ='данные для анализа'!A15 | B15: смешанная обработка с использованием ПК с передачей полученной информации с использованием сети общего пользования Интернет
A16: ='данные для анализа'!A16 | B16: смешанная обработка вышеуказанных персональных данных будет осуществляться с использованием пэвм (информация доступна лишь для строго определенных сотрудников юридического лица) с передачей полученной информации | C16: с использованием сети общего пользования интернет.
A17: ='данные для анализа'!A17 | B17: смешанная обработка с использованием бумажных носителей и пк | C17: с передачей полученной информации по внутренней сети учреждения и сети общего пользования интернет
A18: ='данные для анализа'!A18 | B18: сбор | C18: запись | D18: систематизация | E18: накопление | F18: хранение | G18: уточнение (обновление, изменение) | H18: извлечение | I18: использование | J18: передача (распространение, предоставление, доступ) | K18: обезличивание | L18: блокирование | M18: удаление | N18: уничтожение
A19: ='данные для анализа'!A19 | B19: смешанная обработка персональных данных с передачей данных | C19: с использованием закрытых лвс мвд россии | D19: работа с данными на категорированном компьютерном рабочем месте | E19: работа на арм эвм
A20: ='данные для анализа'!A20 | B20: сбор | C20: систематизация | D20: накопление | E20: хранение | F20: уточнение (обновление,_x000d_ изменение) | G20: использование (в том числе передача) | H20: обезличивание | I20: _x000d_ блокирование | J20: уничтожение будет осуществляться с учетом действующего_x000d_ законодательства.
A21: ='данные для анализа'!A21 | B21: прием | C21: сбор | D21: систематизация | E21: накопление | F21: использование | G21: хранение | H21: уточнение (обновление, изменение) | I21: распространение (в том числе передачу) | J21: уничтожение | K21: блокирование | L21: обезличивание
A22: ='данные для анализа'!A22 | B22: сбор | C22: запись | D22: систематизация | E22: накопление | F22: хранение | G22: уточнение | H22: использование | I22: обезличивание | J22: удаление | K22: уничтожение
A23: ='данные для анализа'!A23 | B23: сбор | C23: систематизация | D23: накопление | E23: хранение | F23: уточнение (обновление, изменение) | G23: использование | H23: распространение (в т. ч. передача) | I23: уничтожение.
A24: ='данные для анализа'!A24 | B24: сбор | C24: запись | D24: систематизация | E24: накопление | F24: хранение | G24: уточнение (обновление, изменение) | H24: извлечение | I24: использование | J24: передача (распространение, предоставление, доступ) | K24: обезличивание | L24: блокирование | M24: удаление | N24: уничтожение
A25: ='данные для анализа'!A25 | B25: обработка персональных данных осуществляется путем смешанной обработки персональных данных. информация | C25: полученная в ходе обработки персональных данных передается по внутренней (локальной) информационной сети юридического лица | D25: которая доступна для строго определенных должностных лиц спбгуэф | E25: в соответствии с приказом ректора.
A26: ='данные для анализа'!A26 | B26: сбор | C26: запись | D26: систематизация | E26: накопление | F26: хранение | G26: уточнение (обновление, изменение) | H26: извлечение | I26: использование | J26: передача (распространение, предоставление, доступ) | K26: блокирование | L26: удаление | M26: уничтожение.
A27: ='данные для анализа'!A27 | B27: сбор | C27: запись | D27: систематизация | E27: накопление | F27: хранение | G27: уточнение (обновление, изменение) | H27: извлечение | I27: использование | J27: передача (распространение, предоставление, доступ) | K27: обезличивание | L27: блокирование | M27: удаление | N27: уничтожение персональных данных.
A28: ='данные для анализа'!A28 | B28: сбор | C28: систематизация | D28: накопление | E28: хранение | F28: уточнение (обновление, изменение) | G28: использование | H28: распространение (в том числе передача) | I28: уничтожение.
A29: ='данные для анализа'!A29 | B29: Смешанная обработка
A30: ='данные для анализа'!A30 | B30: обработка персональных данных осуществляется путём смешанной обработки | C30: включающей сбор | D30: систематизацию | E30: накопление | F30: хранение | G30: уточнение и использование с передачей информации по внутренней сети двгту в специально выделенных помещениях с использованием программных средств аутентификации и авторизации пользователями | H30: включенными в список лиц | I30: допущенных к обработке персональных данных
A31: ='данные для анализа'!A31 | B31: неавтоматизированная обработка — ведение трудовых книжек | C31: личных дел | D31: договоров | E31: списков сотрудников и обучающихся | F31: картотек со сведениями о сотрудниках | G31: картотек со сведениями о студентах | H31: журналов учебных групп | I31: автоматизированная обработка - внесение персональных данных работников в информационные системы: система организации приемной компании ис уз «модус» (подсистема «абитуриент») | J31: автоматизированная информационная библиотечная система марк-sql | K31: автоматизированная система документооборота «дело-предприятие» | L31: система расчета и начисления зарплаты сотрудникам «амба» | M31: система расчета стипендии «амба» | N31: система ведения кадрового учета и расчета зарплаты «контур-персонал» | O31: автоматизированная система бухгалтерского учета для бюджетных учреждений «парус бухгалтерия» | P31: операции с персональными данными - сбор | Q31: хранение | R31: накопление | S31: уточнение | T31: использование | U31: передача | V31: уничтожение данных
A32: ='данные для анализа'!A32 | B32: сбор | C32: запись | D32: систематизация | E32: накопление | F32: хранение | G32: уточнение (обновление, изменени) | H32: извлечение | I32: использование | J32: передача (распространение, предоставление, доступ) | K32: блокирование | L32: удаление | M32: уничтожение персональных данных.
A33: ='данные для анализа'!A33 | B33: сбор | C33: запись | D33: систематизация | E33: накопление | F33: хранение | G33: уточнение (обновление, изменение) | H33: извлечение | I33: использование | J33: передача (распространение, предоставление, доступ) | K33: обезличивание | L33: блокирование | M33: удаление | N33: уничтожение персональных данных
A34: ='данные для анализа'!A34 | B34: смешанная обработка персональных данных с передачей информации по внутренней защищенной локальной сети университета без выхода во внешние сети | C34: передача деперсонализированных общедоступных данных в открытые системы: государственные организации по сбору статистики | D34: вышестоящие федеральные организации | E34: передача данных в организации: банки | F34: налоговая служба | G34: пенсионный фонд | H34: казначейство | I34: государственные организации по сбору статистики | J34: вышестоящие федеральные организации
A35: ='данные для анализа'!A35 | B35: осуществляется смешанная обработка персональных данных
A36: ='данные для анализа'!A36 | B36: сбор | C36: систематизация | D36: накопление | E36: хранение | F36: уточнение (обновление, изменение) | G36: использование | H36: распространение | I36: обезличивание | J36: блокирование | K36: уничтожение
A37: ='данные для анализа'!A37 | B37: сбор | C37: запись | D37: систематизация | E37: накопление | F37: хранение | G37: уточнение | H37: (обновление, изменение) | I37: извлечение | J37: использование | K37: передача (предоставление) | L37: блокирование | M37: удаление | N37: уничтожение. обработка персональных данных будет осуществляться путем смешанной обработки.
A38: ='данные для анализа'!A38 | B38: сбор | C38: запись | D38: систематизация | E38: накопление | F38: хранение | G38: уточнение (обновление, изменение) | H38: извлечение | I38: использование | J38: передача (распространение, предоставление, доступ) | K38: обезличивание | L38: блокирование | M38: удаление | N38: уничтожение
A39: ='данные для анализа'!A39 | B39: сбор | C39: запись | D39: систематизация | E39: накопление | F39: хранение | G39: уточнение (обновление,изменение) | H39: извлечение | I39: использование | J39: передача (распространение, предоставление, доступ) | K39: обезличивание | L39: блокирование | M39: удаление. уничтожение персональных данных.
A40: ='данные для анализа'!A40 | B40: сбор | C40: запись | D40: систематизация | E40: накопление | F40: хранение | G40: уточнение (обновление, изменение) | H40: извлечение | I40: использование | J40: передача (распространение, предоставление, доступ) | K40: обезличивание | L40: блокирование | M40: удаление | N40: уничтожение персональных данных.
...

Sheet разбиение по частям (отфильтр)
A1: данные | B1: слово 1 | C1: слово 2 | D1: слово 3 | E1: слово 4 | F1: слово 5 | G1: слово 6 | H1: слово 7 | I1: слово 8 | J1: слово 9 | K1: слово 10 | L1: слово 11 | M1: слово 12 | N1: слово 13 | O1: слово 14 | P1: слово 15 | Q1: слово 16 | R1: слово 17 | S1: слово 18 | T1: слово 19 | U1: слово 20 | V1: слово 21
A2: ='данные для анализа'!A2 | B2: сбор | C2: систематизация | D2: хранение | E2: использование | F2: уточнение (обновление, изменение) | G2: накопление | H2: обезличивание | I2: блокирование | J2: уничтожение | K2: передача в казначейство | L2: банк | M2: налоговую службу | N2: федеральные фонды
A3: ='данные для анализа'!A3 | B3: сбор | C3: систематизация | D3: накопление | E3: хранение | F3: уточнение (обновление, изменение) | G3: использование | H3: распространение (в том числе передача) | I3: уничтожение персональных данных
A4: ='данные для анализа'!A4 | B4: сбор | C4: запись | D4: систематизация | E4: накопление | F4: хранение | G4: уточнение (обновление, изменение) | H4: извлечение | I4: использование | J4: передача (распространение, предоставление, доступ) | K4: обезличивание | L4: блокирование | M4: удаление | N4: уничтожение персональных данных
A5: ='данные для анализа'!A5 | B5: путем смешанной обработки персональных данных с передачей информации по внутренней сети
A6: ='данные для анализа'!A6 | B6: сбор | C6: систематизация | D6: накопление | E6: хранение | F6: уточнение | G6: распространение | H6: обезличивание | I6: уничтожение
A7: ='данные для анализа'!A7 | B7: смешанная обработка вышеуказанных персональных данных будет осуществляться с использованием пэвм (информация доступна лишь для строго определенных сотрудников юридического лица) | C7: с передачей полученной информации по локальной сети
A8: ='данные для анализа'!A8 | B8: формирование документации | C8: необходимой для осуществления образовательной и научной деятельности
A9: ='данные для анализа'!A9 | B9: сбор | C9: запись | D9: систематизация | E9: накопление | F9: хранение | G9: уточнение (обновление, изменение) | H9: извлечение | I9: использование | J9: передача | K9: распространение | L9: предоставление | M9: блокирование | N9: трансграничная передача | O9: удаление | P9: уничтожение персональных данных
A10: ='данные для анализа'!A10 | B10: сбор | C10: запись | D10: систематизация | E10: накопление | F10: хранение | G10: уточнение (обновления, изменение) | H10: извлечение | I10: использование | J10: передача (распространение, предоставление, доступ) | K10: обезличивание | L10: блокирование | M10: удаление | N10: уничтожение персональных данных
A11: ='данные для анализа'!A11 | B11: сбор | C11: систематизация | D11: накопление | E11: хранение | F11: уточнение | G11: использование | H11: распространение | I11: блокирование | J11: уничтожение
A12: ='данные для анализа'!A12 | B12: сбор | C12: запись | D12: систематизация | E12: накопление | F12: хранение | G12: уточнение (обновление, изменение) | H12: извлечение | I12: использование | J12: передача (распространение, предоставление, доступ) | K12: обезличивание | L12: блокирование | M12: удаление | N12: уничтожение
A13: ='данные для анализа'!A13 | B13: смешанная обработка
A14: ='данные для анализа'!A14 | B14: Смешанная обработка ПД с использованием ПЭВМ (информация доступна лишь для строго определенных сотрудников юридического лица) без передачи полученной информации с использованием сети общего пользования Интернет
A15: ='данные для анализа'!A15 | B15: смешанная обработка с использованием ПК с передачей полученной информации с использованием сети общего пользования Интернет
A16: ='данные для анализа'!A16 | B16: смешанная обработка вышеуказанных персональных данных будет осуществляться с использованием пэвм (информация доступна лишь для строго определенных сотрудников юридического лица) с передачей полученной информации | C16: с использованием сети общего пользования интернет
A17: ='данные для анализа'!A17 | B17: смешанная обработка с использованием бумажных носителей и пк | C17: с передачей полученной информации по внутренней сети учреждения и сети общего пользования интернет
A18: ='данные для анализа'!A18 | B18: сбор | C18: запись | D18: систематизация | E18: накопление | F18: хранение | G18: уточнение (обновление, изменение) | H18: извлечение | I18: использование | J18: передача (распространение, предоставление, доступ) | K18: обезличивание | L18: блокирование | M18: удаление | N18: уничтожение
A19: ='данные для анализа'!A19 | B19: смешанная обработка персональных данных с передачей данных | C19: с использованием закрытых лвс мвд россии | D19: работа с данными на категорированном компьютерном рабочем месте | E19: работа на арм эвм
A20: ='данные для анализа'!A20 | B20: сбор | C20: систематизация | D20: накопление | E20: хранение | F20: уточнение (обновление,_xd_ изменение) | G20: использование (в том числе передача) | H20: обезличивание | I20: _xd_ блокирование | J20: уничтожение будет осуществляться с учетом действующего_xd_ законодательства
A21: ='данные для анализа'!A21 | B21: прием | C21: сбор | D21: систематизация | E21: накопление | F21: использование | G21: хранение | H21: уточнение (обновление, изменение) | I21: распространение (в том числе передачу) | J21: уничтожение | K21: блокирование | L21: обезличивание
A22: ='данные для анализа'!A22 | B22: сбор | C22: запись | D22: систематизация | E22: накопление | F22: хранение | G22: уточнение | H22: использование | I22: обезличивание | J22: удаление | K22: уничтожение
A23: ='данные для анализа'!A23 | B23: сбор | C23: систематизация | D23: накопление | E23: хранение | F23: уточнение (обновление, изменение) | G23: использование | H23: распространение (в т ч передача) | I23: уничтожение
A24: ='данные для анализа'!A24 | B24: сбор | C24: запись | D24: систематизация | E24: накопление | F24: хранение | G24: уточнение (обновление, изменение) | H24: извлечение | I24: использование | J24: передача (распространение, предоставление, доступ) | K24: обезличивание | L24: блокирование | M24: удаление | N24: уничтожение
A25: ='данные для анализа'!A25 | B25: обработка персональных данных осуществляется путем смешанной обработки персональных данных информация | C25: полученная в ходе обработки персональных данных передается по внутренней (локальной) информационной сети юридического лица | D25: которая доступна для строго определенных должностных лиц спбгуэф | E25: в соответствии с приказом ректора
A26: ='данные для анализа'!A26 | B26: сбор | C26: запись | D26: систематизация | E26: накопление | F26: хранение | G26: уточнение (обновление, изменение) | H26: извлечение | I26: использование | J26: передача (распространение, предоставление, доступ) | K26: блокирование | L26: удаление | M26: уничтожение
A27: ='данные для анализа'!A27 | B27: сбор | C27: запись | D27: систематизация | E27: накопление | F27: хранение | G27: уточнение (обновление, изменение) | H27: извлечение | I27: использование | J27: передача (распространение, предоставление, доступ) | K27: обезличивание | L27: блокирование | M27: удаление | N27: уничтожение персональных данных
A28: ='данные для анализа'!A28 | B28: сбор | C28: систематизация | D28: накопление | E28: хранение | F28: уточнение (обновление, изменение) | G28: использование | H28: распространение (в том числе передача) | I28: уничтожение
A29: ='данные для анализа'!A29 | B29: Смешанная обработка
A30: ='данные для анализа'!A30 | B30: обработка персональных данных осуществляется путём смешанной обработки | C30: включающей сбор | D30: систематизацию | E30: накопление | F30: хранение | G30: уточнение и использование с передачей информации по внутренней сети двгту в специально выделенных помещениях с использованием программных средств аутентификации и авторизации пользователями | H30: включенными в список лиц | I30: допущенных к обработке персональных данных
A31: ='данные для анализа'!A31 | B31: неавтоматизированная обработка — ведение трудовых книжек | C31: личных дел | D31: договоров | E31: списков сотрудников и обучающихся | F31: картотек со сведениями о сотрудниках | G31: картотек со сведениями о студентах | H31: журналов учебных групп | I31: автоматизированная обработка - внесение персональных данных работников в информационные системы: система организации приемной компании ис уз «модус» (подсистема «абитуриент») | J31: автоматизированная информационная библиотечная система марк-sql | K31: автоматизированная система документооборота «дело-предприятие» | L31: система расчета и начисления зарплаты сотрудникам «амба» | M31: система расчета стипендии «амба» | N31: система ведения кадрового учета и расчета зарплаты «контур-персонал» | O31: автоматизированная система бухгалтерского учета для бюджетных учреждений «парус бухгалтерия» | P31: операции с персональными данными - сбор | Q31: хранение | R31: накопление | S31: уточнение | T31: использование | U31: передача | V31: уничтожение данных
A32: ='данные для анализа'!A32 | B32: сбор | C32: запись | D32: систематизация | E32: накопление | F32: хранение | G32: уточнение (обновление, изменени) | H32: извлечение | I32: использование | J32: передача (распространение, предоставление, доступ) | K32: блокирование | L32: удаление | M32: уничтожение персональных данных
A33: ='данные для анализа'!A33 | B33: сбор | C33: запись | D33: систематизация | E33: накопление | F33: хранение | G33: уточнение (обновление, изменение) | H33: извлечение | I33: использование | J33: передача (распространение, предоставление, доступ) | K33: обезличивание | L33: блокирование | M33: удаление | N33: уничтожение персональных данных
A34: ='данные для анализа'!A34 | B34: смешанная обработка персональных данных с передачей информации по внутренней защищенной локальной сети университета без выхода во внешние сети | C34: передача деперсонализированных общедоступных данных в открытые системы: государственные организации по сбору статистики | D34: вышестоящие федеральные организации | E34: передача данных в организации: банки | F34: налоговая служба | G34: пенсионный фонд | H34: казначейство | I34: государственные организации по сбору статистики | J34: вышестоящие федеральные организации
A35: ='данные для анализа'!A35 | B35: осуществляется смешанная обработка персональных данных
A36: ='данные для анализа'!A36 | B36: сбор | C36: систематизация | D36: накопление | E36: хранение | F36: уточнение (обновление, изменение) | G36: использование | H36: распространение | I36: обезличивание | J36: блокирование | K36: уничтожение
A37: ='данные для анализа'!A37 | B37: сбор | C37: запись | D37: систематизация | E37: накопление | F37: хранение | G37: уточнение | H37: (обновление, изменение) | I37: извлечение | J37: использование | K37: передача (предоставление) | L37: блокирование | M37: удаление | N37: уничтожение обработка персональных данных будет осуществляться путем смешанной обработки
A38: ='данные для анализа'!A38 | B38: сбор | C38: запись | D38: систематизация | E38: накопление | F38: хранение | G38: уточнение (обновление, изменение) | H38: извлечение | I38: использование | J38: передача (распространение, предоставление, доступ) | K38: обезличивание | L38: блокирование | M38: удаление | N38: уничтожение
A39: ='данные для анализа'!A39 | B39: сбор | C39: запись | D39: систематизация | E39: накопление | F39: хранение | G39: уточнение (обновление,изменение) | H39: извлечение | I39: использование | J39: передача (распространение, предоставление, доступ) | K39: обезличивание | L39: блокирование | M39: удаление уничтожение персональных данных
A40: ='данные для анализа'!A40 | B40: сбор | C40: запись | D40: систематизация | E40: накопление | F40: хранение | G40: уточнение (обновление, изменение) | H40: извлечение | I40: использование | J40: передача (распространение, предоставление, доступ) | K40: обезличивание | L40: блокирование | M40: удаление | N40: уничтожение персональных данных
...

Sheet разбиение по частям (лемматиз)
A1: данные | B1: слово 1 | C1: слово 2 | D1: слово 3 | E1: слово 4 | F1: слово 5 | G1: слово 6 | H1: слово 7 | I1: слово 8 | J1: слово 9 | K1: слово 10 | L1: слово 11 | M1: слово 12 | N1: слово 13 | O1: слово 14 | P1: слово 15 | Q1: слово 16 | R1: слово 17 | S1: слово 18 | T1: слово 19 | U1: слово 20 | V1: слово 21
A2: ='данные для анализа'!A2 | B2: сбор | C2: систематизация | D2: хранение | E2: использование | F2: уточнение | G2: обновление | H2: изменение | I2: накопление | J2: обезличивание | K2: блокирование | L2: уничтожение | M2: передача | N2: казначейство | O2: банк | P2: налоговый | Q2: служба | R2: федеральный | S2: фонд
A3: ='данные для анализа'!A3 | B3: сбор | C3: систематизация | D3: накопление | E3: хранение | F3: уточнение | G3: обновление | H3: изменение | I3: использование | J3: распространение | K3: число | L3: передача | M3: уничтожение | N3: персональный | O3: данные
A4: ='данные для анализа'!A4 | B4: сбор | C4: запись | D4: систематизация | E4: накопление | F4: хранение | G4: уточнение | H4: обновление | I4: изменение | J4: извлечение | K4: использование | L4: передача | M4: распространение | N4: предоставление | O4: доступ | P4: обезличивание | Q4: блокирование | R4: удаление | S4: уничтожение | T4: персональный | U4: данные
A5: ='данные для анализа'!A5 | B5: путем | C5: смешать | D5: обработка | E5: персональный | F5: данные | G5: передача | H5: информация | I5: внутренний | J5: сеть
A6: ='данные для анализа'!A6 | B6: сбор | C6: систематизация | D6: накопление | E6: хранение | F6: уточнение | G6: распространение | H6: обезличивание | I6: уничтожение
A7: ='данные для анализа'!A7 | B7: смешать | C7: обработка | D7: вышеуказанный | E7: персональный | F7: данные | G7: быть | H7: осуществляться | I7: использование | J7: пэвм | K7: информация | L7: доступный | M7: лишь | N7: строго | O7: определенный | P7: сотрудник | Q7: юридический | R7: лицо | S7: передача | T7: получать | U7: информация | V7: локальный | W7: сеть
A8: ='данные для анализа'!A8 | B8: формирование | C8: документация | D8: необходимый | E8: осуществление | F8: образовательный | G8: научный | H8: деятельность
A9: ='данные для анализа'!A9 | B9: сбор | C9: запись | D9: систематизация | E9: накопление | F9: хранение | G9: уточнение | H9: обновление | I9: изменение | J9: извлечение | K9: использование | L9: передача | M9: распространение | N9: предоставление | O9: блокирование | P9: трансграничный | Q9: передача | R9: удаление | S9: уничтожение | T9: персональный | U9: данные
A10: ='данные для анализа'!A10 | B10: сбор | C10: запись | D10: систематизация | E10: накопление | F10: хранение | G10: уточнение | H10: обновление | I10: изменение | J10: извлечение | K10: использование | L10: передача | M10: распространение | N10: предоставление | O10: доступ | P10: обезличивание | Q10: блокирование | R10: удаление | S10: уничтожение | T10: персональный | U10: данные
A11: ='данные для анализа'!A11 | B11: сбор | C11: систематизация | D11: накопление | E11: хранение | F11: уточнение | G11: использование | H11: распространение | I11: блокирование | J11: уничтожение
A12: ='данные для анализа'!A12 | B12: сбор | C12: запись | D12: систематизация | E12: накопление | F12: хранение | G12: уточнение | H12: обновление | I12: изменение | J12: извлечение | K12: использование | L12: передача | M12: распространение | N12: предоставление | O12: доступ | P12: обезличивание | Q12: блокирование | R12: удаление | S12: уничтожение
A13: ='данные для анализа'!A13 | B13: смешать | C13: обработка
A14: ='данные для анализа'!A14 | B14: смешать | C14: обработка | D14: использование | E14: пэвм | F14: информация | G14: доступный | H14: лишь | I14: строго | J14: определенный | K14: сотрудник | L14: юридический | M14: лицо | N14: передача | O14: получать | P14: информация | Q14: использование | R14: сеть | S14: общий | T14: пользование | U14: интернет
A15: ='данные для анализа'!A15 | B15: смешать | C15: обработка | D15: использование | E15: передача | F15: получать | G15: информация | H15: использование | I15: сеть | J15: общий | K15: пользование | L15: интернет
A16: ='данные для анализа'!A16 | B16: смешать | C16: обработка | D16: вышеуказанный | E16: персональный | F16: данные | G16: быть | H16: осуществляться | I16: использование | J16: пэвм | K16: информация | L16: доступный | M16: лишь | N16: строго | O16: определенный | P16: сотрудник | Q16: юридический | R16: лицо | S16: передача | T16: получать | U16: информация | V16: использование | W16: сеть | X16: общий | Y16: пользование | Z16: интернет
A17: ='данные для анализа'!A17 | B17: смешать | C17: обработка | D17: использование | E17: бумажный | F17: носитель | G17: передача | H17: получать | I17: информация | J17: внутренний | K17: сеть | L17: учреждение | M17: сеть | N17: общий | O17: пользование | P17: интернет
A18: ='данные для анализа'!A18 | B18: сбор | C18: запись | D18: систематизация | E18: накопление | F18: хранение | G18: уточнение | H18: обновление | I18: изменение | J18: извлечение | K18: использование | L18: передача | M18: распространение | N18: предоставление | O18: доступ | P18: обезличивание | Q18: блокирование | R18: удаление | S18: уничтожение
A19: ='данные для анализа'!A19 | B19: смешать | C19: обработка | D19: персональный | E19: данные | F19: передача | G19: данные | H19: использование | I19: закрытый | J19: россия | K19: работа | L19: данные | M19: категорированный | N19: компьютерный | O19: рабочий | P19: место | Q19: работа
A20: ='данные для анализа'!A20 | B20: сбор | C20: систематизация | D20: накопление | E20: хранение | F20: уточнение | G20: обновление | H20: изменение | I20: использование | J20: число | K20: передача | L20: обезличивание | M20: блокирование | N20: уничтожение | O20: быть | P20: осуществляться | Q20: учет | R20: действующий | S20: законодательство
A21: ='данные для анализа'!A21 | B21: прием | C21: сбор | D21: систематизация | E21: накопление | F21: использование | G21: хранение | H21: уточнение | I21: обновление | J21: изменение | K21: распространение | L21: число | M21: передача | N21: уничтожение | O21: блокирование | P21: обезличивание
A22: ='данные для анализа'!A22 | B22: сбор | C22: запись | D22: систематизация | E22: накопление | F22: хранение | G22: уточнение | H22: использование | I22: обезличивание | J22: удаление | K22: уничтожение
A23: ='данные для анализа'!A23 | B23: сбор | C23: систематизация | D23: накопление | E23: хранение | F23: уточнение | G23: обновление | H23: изменение | I23: использование | J23: распространение | K23: передача | L23: уничтожение
A24: ='данные для анализа'!A24 | B24: сбор | C24: запись | D24: систематизация | E24: накопление | F24: хранение | G24: уточнение | H24: обновление | I24: изменение | J24: извлечение | K24: использование | L24: передача | M24: распространение | N24: предоставление | O24: доступ | P24: обезличивание | Q24: блокирование | R24: удаление | S24: уничтожение
A25: ='данные для анализа'!A25 | B25: обработка | C25: персональный | D25: данные | E25: осуществляться | F25: путем | G25: смешанный | H25: обработка | I25: персональный | J25: данные | K25: информация | L25: получать | M25: обработка | N25: персональный | O25: данные | P25: передаваться | Q25: внутренний | R25: локальный | S25: информационный | T25: сеть | U25: юридический | V25: лицо | W25: который | X25: доступный | Y25: строго | Z25: определенный | AA25: должностной | AB25: лицо | AC25: спбгуэфа | AD25: соответствие | AE25: приказ | AF25: ректор
A26: ='данные для анализа'!A26 | B26: сбор | C26: запись | D26: систематизация | E26: накопление | F26: хранение | G26: уточнение | H26: обновление | I26: изменение | J26: извлечение | K26: использование | L26: передача | M26: распространение | N26: предоставление | O26: доступ | P26: блокирование | Q26: удаление | R26: уничтожение
A27: ='данные для анализа'!A27 | B27: сбор | C27: запись | D27: систематизация | E27: накопление | F27: хранение | G27: уточнение | H27: обновление | I27: изменение | J27: извлечение | K27: использование | L27: передача | M27: распространение | N27: предоставление | O27: доступ | P27: обезличивание | Q27: блокирование | R27: удаление | S27: уничтожение | T27: персональный | U27: данные
A28: ='данные для анализа'!A28 | B28: сбор | C28: систематизация | D28: накопление | E28: хранение | F28: уточнение | G28: обновление | H28: изменение | I28: использование | J28: распространение | K28: число | L28: передача | M28: уничтожение
A29: ='данные для анализа'!A29 | B29: смешать | C29: обработка
A30: ='данные для анализа'!A30 | B30: обработка | C30: персональный | D30: данные | E30: осуществляться | F30: путем | G30: смешанный | H30: обработка | I30: включать | J30: сбор | K30: систематизация | L30: накопление | M30: хранение | N30: уточнение | O30: использование | P30: передача | Q30: информация | R30: внутренний | S30: сеть | T30: двгту | U30: специально | V30: выделять | W30: помещение | X30: использование | Y30: программный | Z30: средство | AA30: аутентификация | AB30: авторизация | AC30: пользователь | AD30: включать | AE30: список | AF30: лицо | AG30: допускать | AH30: обработка | AI30: персональный | AJ30: данные
A31: ='данные для анализа'!A31 | B31: неавтоматизированный | C31: обработка | D31: ведение | E31: трудовой | F31: книжка | G31: личный | H31: дело | I31: договор | J31: список | K31: сотрудник | L31: обучающийся | M31: картотека | N31: сведение | O31: сотрудник | P31: картотека | Q31: сведение | R31: студент | S31: журнал | T31: учебный | U31: группа | V31: автоматизированный | W31: обработка | X31: внесение | Y31: персональный | Z31: данные | AA31: работник | AB31: информационный | AC31: система | AD31: система | AE31: организация | AF31: приемная | AG31: компания | AH31: модус | AI31: подсистема | AJ31: абитуриент | AK31: автоматизированный | AL31: информационный | AM31: библиотечный | AN31: система | AO31: марк | AP31: автоматизированный | AQ31: система | AR31: документооборот | AS31: дело | AT31: предприятие | AU31: система | AV31: расчет | AW31: начисление | AX31: зарплата | AY31: сотрудник | AZ31: амба | BA31: система | BB31: расчет | BC31: стипендия | BD31: амба | BE31: система | BF31: ведение | BG31: кадровый | BH31: учет | BI31: расчет | BJ31: зарплата | BK31: контур | BL31: персонал | BM31: автоматизированный | BN31: система | BO31: бухгалтерский | BP31: учет | BQ31: бюджетный | BR31: учреждение | BS31: парус | BT31: бухгалтерия | BU31: операция | BV31: персональный | BW31: данные | BX31: сбор | BY31: хранение | BZ31: накопление | CA31: уточнение | CB31: использование | CC31: передача | CD31: уничтожение | CE31: данный
A32: ='данные для анализа'!A32 | B32: сбор | C32: запись | D32: систематизация | E32: накопление | F32: хранение | G32: уточнение | H32: обновление | I32: изменень | J32: извлечение | K32: использование | L32: передача | M32: распространение | N32: предоставление | O32: доступ | P32: блокирование | Q32: удаление | R32: уничтожение | S32: персональный | T32: данные
A33: ='данные для анализа'!A33 | B33: сбор | C33: запись | D33: систематизация | E33: накопление | F33: хранение | G33: уточнение | H33: обновление | I33: изменение | J33: извлечение | K33: использование | L33: передача | M33: распространение | N33: предоставление | O33: доступ | P33: обезличивание | Q33: блокирование | R33: удаление | S33: уничтожение | T33: персональный | U33: данные
A34: ='данные для анализа'!A34 | B34: смешать | C34: обработка | D34: персональный | E34: данные | F34: передача | G34: информация | H34: внутренний | I34: защищать | J34: локальный | K34: сеть | L34: университет | M34: выход | N34: внешний | O34: сеть | P34: передача | Q34: деперсонализировать | R34: общедоступный | S34: данные | T34: открытый | U34: система | V34: государственный | W34: организация | X34: сбор | Y34: статистика | Z34: вышестоящий | AA34: федеральный | AB34: организация | AC34: передача | AD34: данные | AE34: организация | AF34: банка | AG34: налоговый | AH34: служба | AI34: пенсионный | AJ34: фонд | AK34: казначейство | AL34: государственный | AM34: организация | AN34: сбор | AO34: статистика | AP34: вышестоящий | AQ34: федеральный | AR34: организация
A35: ='данные для анализа'!A35 | B35: осуществляться | C35: смешать | D35: обработка | E35: персональный | F35: данный
A36: ='данные для анализа'!A36 | B36: сбор | C36: систематизация | D36: накопление | E36: хранение | F36: уточнение | G36: обновление | H36: изменение | I36: использование | J36: распространение | K36: обезличивание | L36: блокирование | M36: уничтожение
A37: ='данные для анализа'!A37 | B37: сбор | C37: запись | D37: систематизация | E37: накопление | F37: хранение | G37: уточнение | H37: обновление | I37: изменение | J37: извлечение | K37: использование | L37: передача | M37: предоставление | N37: блокирование | O37: удаление | P37: уничтожение | Q37: обработка | R37: персональный | S37: данные | T37: быть | U37: осуществляться | V37: путем | W37: смешанный | X37: обработка
A38: ='данные для анализа'!A38 | B38: сбор | C38: запись | D38: систематизация | E38: накопление | F38: хранение | G38: уточнение | H38: обновление | I38: изменение | J38: извлечение | K38: использование | L38: передача | M38: распространение | N38: предоставление | O38: доступ | P38: обезличивание | Q38: блокирование | R38: удаление | S38: уничтожение
A39: ='данные для анализа'!A39 | B39: сбор | C39: запись | D39: систематизация | E39: накопление | F39: хранение | G39: уточнение | H39: обновление | I39: изменение | J39: извлечение | K39: использование | L39: передача | M39: распространение | N39: предоставление | O39: доступ | P39: обезличивание | Q39: блокирование | R39: удаление | S39: уничтожение | T39: персональный | U39: данные
A40: ='данные для анализа'!A40 | B40: сбор | C40: запись | D40: систематизация | E40: накопление | F40: хранение | G40: уточнение | H40: обновление | I40: изменение | J40: извлечение | K40: использование | L40: передача | M40: распространение | N40: предоставление | O40: доступ | P40: обезличивание | Q40: блокирование | R40: удаление | S40: уничтожение | T40: персональный | U40: данные
...

Sheet кластеры
B1: rkn:name_full | D1: сбор | E1: запись | F1: систематизация | G1: накопление | H1: хранение | I1: уточнение (обновление, изменение) | J1: извлечение | K1: использование | L1: передача (распространение, предоставление, доступ) | M1: удаление | N1: уничтожение
A2: ='данные для анализа'!A2 | B2: ='данные для анализа'!B2 | C2: =SUM(D2:V2) | D2: 1 | F2: 1 | G2: 1 | H2: 1 | I2: 1 | K2: 1 | L2: 1 | N2: 1
A3: ='данные для анализа'!A3 | B3: ='данные для анализа'!B3 | C3: =SUM(D3:V3) | D3: 1 | F3: 1 | G3: 1 | H3: 1 | I3: 1 | K3: 1 | L3: 1 | N3: 1
A4: ='данные для анализа'!A4 | B4: ='данные для анализа'!B4 | C4: =SUM(D4:V4) | D4: 1 | E4: 1 | F4: 1 | G4: 1 | H4: 1 | I4: 1 | J4: 1 | K4: 1 | L4: 1 | M4: 1 | N4: 1
A5: ='данные для анализа'!A5 | B5: ='данные для анализа'!B5 | C5: =SUM(D5:V5) | L5: 1
A6: ='данные для анализа'!A6 | B6: ='данные для анализа'!B6 | C6: =SUM(D6:V6) | D6: 1 | F6: 1 | G6: 1 | H6: 1 | I6: 1 | L6: 1 | N6: 1
A7: ='данные для анализа'!A7 | B7: ='данные для анализа'!B7 | C7: =SUM(D7:V7) | K7: 1 | L7: 1
A8: ='данные для анализа'!A8 | B8: ='данные для анализа'!B8 | C8: =SUM(D8:V8)
A9: ='данные для анализа'!A9 | B9: ='данные для анализа'!B9 | C9: =SUM(D9:V9) | D9: 1 | E9: 1 | F9: 1 | G9: 1 | H9: 1 | I9: 1 | J9: 1 | K9: 1 | L9: 1 | M9: 1 | N9: 1
A10: ='данные для анализа'!A10 | B10: ='данные для анализа'!B10 | C10: =SUM(D10:V10) | D10: 1 | E10: 1 | F10: 1 | G10: 1 | H10: 1 | I10: 1 | J10: 1 | K10: 1 | L10: 1 | M10: 1 | N10: 1
A11: ='данные для анализа'!A11 | B11: ='данные для анализа'!B11 | C11: =SUM(D11:V11) | D11: 1 | F11: 1 | G11: 1 | H11: 1 | I11: 1 | K11: 1 | L11: 1 | N11: 1
A12: ='данные для анализа'!A12 | B12: ='данные для анализа'!B12 | C12: =SUM(D12:V12) | D12: 1 | E12: 1 | F12: 1 | G12: 1 | H12: 1 | I12: 1 | J12: 1 | K12: 1 | L12: 1 | M12: 1 | N12: 1
A13: ='данные для анализа'!A13 | B13: ='данные для анализа'!B13 | C13: =SUM(D13:V13)
A14: ='данные для анализа'!A14 | B14: ='данные для анализа'!B14 | C14: =SUM(D14:V14) | K14: 1 | L14: 1
A15: ='данные для анализа'!A15 | B15: ='данные для анализа'!B15 | C15: =SUM(D15:V15) | K15: 1 | L15: 1
A16: ='данные для анализа'!A16 | B16: ='данные для анализа'!B16 | C16: =SUM(D16:V16) | K16: 1 | L16: 1
A17: ='данные для анализа'!A17 | B17: ='данные для анализа'!B17 | C17: =SUM(D17:V17) | K17: 1 | L17: 1
A18: ='данные для анализа'!A18 | B18: ='данные для анализа'!B18 | C18: =SUM(D18:V18) | D18: 1 | E18: 1 | F18: 1 | G18: 1 | H18: 1 | I18: 1 | J18: 1 | K18: 1 | L18: 1 | M18: 1 | N18: 1
A19: ='данные для анализа'!A19 | B19: ='данные для анализа'!B19 | C19: =SUM(D19:V19) | K19: 1 | L19: 1
A20: ='данные для анализа'!A20 | B20: ='данные для анализа'!B20 | C20: =SUM(D20:V20) | D20: 1 | F20: 1 | G20: 1 | H20: 1 | I20: 1 | K20: 1 | L20: 1 | N20: 1
A21: ='данные для анализа'!A21 | B21: ='данные для анализа'!B21 | C21: =SUM(D21:V21) | D21: 1 | F21: 1 | G21: 1 | H21: 1 | I21: 1 | K21: 1 | L21: 1 | N21: 1
A22: ='данные для анализа'!A22 | B22: ='данные для анализа'!B22 | C22: =SUM(D22:V22) | D22: 1 | E22: 1 | F22: 1 | G22: 1 | H22: 1 | I22: 1 | K22: 1 | M22: 1 | N22: 1
A23: ='данные для анализа'!A23 | B23: ='данные для анализа'!B23 | C23: =SUM(D23:V23) | D23: 1 | F23: 1 | G23: 1 | H23: 1 | I23: 1 | K23: 1 | L23: 1 | N23: 1
A24: ='данные для анализа'!A24 | B24: ='данные для анализа'!B24 | C24: =SUM(D24:V24) | D24: 1 | E24: 1 | F24: 1 | G24: 1 | H24: 1 | I24: 1 | J24: 1 | K24: 1 | L24: 1 | M24: 1 | N24: 1
A25: ='данные для анализа'!A25 | B25: ='данные для анализа'!B25 | C25: =SUM(D25:V25)
A26: ='данные для анализа'!A26 | B26: ='данные для анализа'!B26 | C26: =SUM(D26:V26) | D26: 1 | E26: 1 | F26: 1 | G26: 1 | H26: 1 | I26: 1 | J26: 1 | K26: 1 | L26: 1 | M26: 1 | N26: 1
A27: ='данные для анализа'!A27 | B27: ='данные для анализа'!B27 | C27: =SUM(D27:V27) | D27: 1 | E27: 1 | F27: 1 | G27: 1 | H27: 1 | I27: 1 | J27: 1 | K27: 1 | L27: 1 | M27: 1 | N27: 1
A28: ='данные для анализа'!A28 | B28: ='данные для анализа'!B28 | C28: =SUM(D28:V28) | D28: 1 | F28: 1 | G28: 1 | H28: 1 | I28: 1 | K28: 1 | L28: 1 | N28: 1
A29: ='данные для анализа'!A29 | B29: ='данные для анализа'!B29 | C29: =SUM(D29:V29)
A30: ='данные для анализа'!A30 | B30: ='данные для анализа'!B30 | C30: =SUM(D30:V30) | D30: 1 | F30: 1 | G30: 1 | H30: 1 | I30: 1 | K30: 1 | L30: 1
A31: ='данные для анализа'!A31 | B31: ='данные для анализа'!B31 | C31: =SUM(D31:V31) | D31: 1 | G31: 1 | H31: 1 | I31: 1 | K31: 1 | L31: 1 | N31: 1
A32: ='данные для анализа'!A32 | B32: ='данные для анализа'!B32 | C32: =SUM(D32:V32) | D32: 1 | E32: 1 | F32: 1 | G32: 1 | H32: 1 | I32: 1 | J32: 1 | K32: 1 | L32: 1 | M32: 1 | N32: 1
A33: ='данные для анализа'!A33 | B33: ='данные для анализа'!B33 | C33: =SUM(D33:V33) | D33: 1 | E33: 1 | F33: 1 | G33: 1 | H33: 1 | I33: 1 | J33: 1 | K33: 1 | L33: 1 | M33: 1 | N33: 1
A34: ='данные для анализа'!A34 | B34: ='данные для анализа'!B34 | C34: =SUM(D34:V34) | D34: 1 | L34: 1
A35: ='данные для анализа'!A35 | B35: ='данные для анализа'!B35 | C35: =SUM(D35:V35)
A36: ='данные для анализа'!A36 | B36: ='данные для анализа'!B36 | C36: =SUM(D36:V36) | D36: 1 | F36: 1 | G36: 1 | H36: 1 | I36: 1 | K36: 1 | L36: 1 | N36: 1
A37: ='данные для анализа'!A37 | B37: ='данные для анализа'!B37 | C37: =SUM(D37:V37) | D37: 1 | E37: 1 | F37: 1 | G37: 1 | H37: 1 | I37: 1 | J37: 1 | K37: 1 | L37: 1 | M37: 1 | N37: 1
A38: ='данные для анализа'!A38 | B38: ='данные для анализа'!B38 | C38: =SUM(D38:V38) | D38: 1 | E38: 1 | F38: 1 | G38: 1 | H38: 1 | I38: 1 | J38: 1 | K38: 1 | L38: 1 | M38: 1 | N38: 1
A39: ='данные для анализа'!A39 | B39: ='данные для анализа'!B39 | C39: =SUM(D39:V39) | D39: 1 | E39: 1 | F39: 1 | G39: 1 | H39: 1 | I39: 1 | J39: 1 | K39: 1 | L39: 1 | M39: 1 | N39: 1
A40: ='данные для анализа'!A40 | B40: ='данные для анализа'!B40 | C40: =SUM(D40:V40) | D40: 1 | E40: 1 | F40: 1 | G40: 1 | H40: 1 | I40: 1 | J40: 1 | K40: 1 | L40: 1 | M40: 1 | N40: 1
...
